{
 "cells": [
  {
   "cell_type": "markdown",
   "id": "3ad68a98",
   "metadata": {},
   "source": [
    "# sentiment-analysis"
   ]
  },
  {
   "cell_type": "code",
   "execution_count": 3,
   "id": "ec271d73",
   "metadata": {},
   "outputs": [],
   "source": [
    "import numpy as np\n",
    "\n",
    "docs = ['go india',\n",
    "        'india india',\n",
    "        'hip hip hurray',\n",
    "        'jeetega bhai jeetega india jeetega',\n",
    "        'bharat mata ki jai',\n",
    "        'kohli kohli',\n",
    "        'sachin sachin',\n",
    "        'dhoni dhoni',\n",
    "        'modi ji ki jai',\n",
    "        'inquilab zindabad']"
   ]
  },
  {
   "cell_type": "code",
   "execution_count": 4,
   "id": "024efad2",
   "metadata": {},
   "outputs": [],
   "source": [
    "from keras.preprocessing.text import Tokenizer\n",
    "tokenizer = Tokenizer()"
   ]
  },
  {
   "cell_type": "code",
   "execution_count": 5,
   "id": "ce4e4783",
   "metadata": {},
   "outputs": [],
   "source": [
    "tokenizer.fit_on_texts(docs)"
   ]
  },
  {
   "cell_type": "code",
   "execution_count": 6,
   "id": "8cc4745c",
   "metadata": {},
   "outputs": [
    {
     "data": {
      "text/plain": [
       "17"
      ]
     },
     "execution_count": 6,
     "metadata": {},
     "output_type": "execute_result"
    }
   ],
   "source": [
    "len(tokenizer.word_index)"
   ]
  },
  {
   "cell_type": "code",
   "execution_count": 7,
   "id": "aa43eb7f",
   "metadata": {},
   "outputs": [
    {
     "data": {
      "text/plain": [
       "[[9, 1],\n",
       " [1, 1],\n",
       " [3, 3, 10],\n",
       " [2, 11, 2, 1, 2],\n",
       " [12, 13, 4, 5],\n",
       " [6, 6],\n",
       " [7, 7],\n",
       " [8, 8],\n",
       " [14, 15, 4, 5],\n",
       " [16, 17]]"
      ]
     },
     "execution_count": 7,
     "metadata": {},
     "output_type": "execute_result"
    }
   ],
   "source": [
    "sequences = tokenizer.texts_to_sequences(docs)\n",
    "sequences"
   ]
  },
  {
   "cell_type": "code",
   "execution_count": 8,
   "id": "dea7fa80",
   "metadata": {},
   "outputs": [
    {
     "data": {
      "text/plain": [
       "array([[ 9,  1,  0,  0,  0],\n",
       "       [ 1,  1,  0,  0,  0],\n",
       "       [ 3,  3, 10,  0,  0],\n",
       "       [ 2, 11,  2,  1,  2],\n",
       "       [12, 13,  4,  5,  0],\n",
       "       [ 6,  6,  0,  0,  0],\n",
       "       [ 7,  7,  0,  0,  0],\n",
       "       [ 8,  8,  0,  0,  0],\n",
       "       [14, 15,  4,  5,  0],\n",
       "       [16, 17,  0,  0,  0]])"
      ]
     },
     "execution_count": 8,
     "metadata": {},
     "output_type": "execute_result"
    }
   ],
   "source": [
    "from keras.utils import pad_sequences\n",
    "sequences = pad_sequences(sequences,padding='post')\n",
    "sequences"
   ]
  },
  {
   "cell_type": "code",
   "execution_count": 11,
   "id": "8884a3b8",
   "metadata": {},
   "outputs": [
    {
     "name": "stdout",
     "output_type": "stream",
     "text": [
      "Model: \"sequential_1\"\n",
      "_________________________________________________________________\n",
      " Layer (type)                Output Shape              Param #   \n",
      "=================================================================\n",
      " embedding (Embedding)       (None, 5, 2)              34        \n",
      "                                                                 \n",
      "=================================================================\n",
      "Total params: 34 (136.00 Byte)\n",
      "Trainable params: 34 (136.00 Byte)\n",
      "Non-trainable params: 0 (0.00 Byte)\n",
      "_________________________________________________________________\n"
     ]
    }
   ],
   "source": [
    "from keras.models import Sequential\n",
    "from keras.layers import Embedding\n",
    "model = Sequential()\n",
    "model.add(Embedding(17,output_dim=2,input_length=5))\n",
    "\n",
    "model.summary()"
   ]
  },
  {
   "cell_type": "code",
   "execution_count": 12,
   "id": "966ff395",
   "metadata": {},
   "outputs": [],
   "source": [
    "model.compile('adam','accuracy')"
   ]
  },
  {
   "cell_type": "code",
   "execution_count": 16,
   "id": "fef7606f",
   "metadata": {},
   "outputs": [],
   "source": [
    "from keras.datasets import imdb\n",
    "from keras.preprocessing.text import Tokenizer\n",
    "from keras.utils import pad_sequences\n",
    "from keras import Sequential\n",
    "from keras.layers import Dense,SimpleRNN,Embedding,Flatten"
   ]
  },
  {
   "cell_type": "code",
   "execution_count": 18,
   "id": "1b0808b4",
   "metadata": {},
   "outputs": [
    {
     "name": "stdout",
     "output_type": "stream",
     "text": [
      "Downloading data from https://storage.googleapis.com/tensorflow/tf-keras-datasets/imdb.npz\n",
      "17464789/17464789 [==============================] - 2s 0us/step\n"
     ]
    }
   ],
   "source": [
    "(X_train,y_train),(X_test,y_test) = imdb.load_data()"
   ]
  },
  {
   "cell_type": "code",
   "execution_count": 20,
   "id": "ed6ffb04",
   "metadata": {},
   "outputs": [],
   "source": [
    "X_train = pad_sequences(X_train,padding='post',maxlen=50)\n",
    "X_test = pad_sequences(X_test,padding='post',maxlen=50)"
   ]
  },
  {
   "cell_type": "code",
   "execution_count": 21,
   "id": "4fa260ac",
   "metadata": {},
   "outputs": [
    {
     "data": {
      "text/plain": [
       "(25000, 50)"
      ]
     },
     "execution_count": 21,
     "metadata": {},
     "output_type": "execute_result"
    }
   ],
   "source": [
    "X_train.shape"
   ]
  },
  {
   "cell_type": "code",
   "execution_count": 27,
   "id": "7256e90c",
   "metadata": {},
   "outputs": [
    {
     "name": "stdout",
     "output_type": "stream",
     "text": [
      "Model: \"sequential_5\"\n",
      "_________________________________________________________________\n",
      " Layer (type)                Output Shape              Param #   \n",
      "=================================================================\n",
      " embedding_4 (Embedding)     (None, None, 2)           20000     \n",
      "                                                                 \n",
      " simple_rnn_2 (SimpleRNN)    (None, 32)                1120      \n",
      "                                                                 \n",
      " dense_2 (Dense)             (None, 1)                 33        \n",
      "                                                                 \n",
      "=================================================================\n",
      "Total params: 21153 (82.63 KB)\n",
      "Trainable params: 21153 (82.63 KB)\n",
      "Non-trainable params: 0 (0.00 Byte)\n",
      "_________________________________________________________________\n"
     ]
    }
   ],
   "source": [
    "from keras.models import Sequential\n",
    "from keras.layers import Embedding, SimpleRNN, Dense\n",
    "\n",
    "model = Sequential()\n",
    "model.add(Embedding(input_dim=10000, output_dim=2))  # Corrected the arguments\n",
    "model.add(SimpleRNN(32, return_sequences=False))\n",
    "model.add(Dense(1, activation='sigmoid'))\n",
    "\n",
    "model.summary()\n"
   ]
  },
  {
   "cell_type": "code",
   "execution_count": 28,
   "id": "005e4d0d",
   "metadata": {},
   "outputs": [
    {
     "name": "stdout",
     "output_type": "stream",
     "text": [
      "Epoch 1/5\n"
     ]
    },
    {
     "ename": "InvalidArgumentError",
     "evalue": "Graph execution error:\n\nDetected at node 'sequential_5/embedding_4/embedding_lookup' defined at (most recent call last):\n    File \"C:\\Users\\jainh\\anaconda3\\lib\\runpy.py\", line 197, in _run_module_as_main\n      return _run_code(code, main_globals, None,\n    File \"C:\\Users\\jainh\\anaconda3\\lib\\runpy.py\", line 87, in _run_code\n      exec(code, run_globals)\n    File \"C:\\Users\\jainh\\anaconda3\\lib\\site-packages\\ipykernel_launcher.py\", line 17, in <module>\n      app.launch_new_instance()\n    File \"C:\\Users\\jainh\\anaconda3\\lib\\site-packages\\traitlets\\config\\application.py\", line 846, in launch_instance\n      app.start()\n    File \"C:\\Users\\jainh\\anaconda3\\lib\\site-packages\\ipykernel\\kernelapp.py\", line 712, in start\n      self.io_loop.start()\n    File \"C:\\Users\\jainh\\anaconda3\\lib\\site-packages\\tornado\\platform\\asyncio.py\", line 199, in start\n      self.asyncio_loop.run_forever()\n    File \"C:\\Users\\jainh\\anaconda3\\lib\\asyncio\\base_events.py\", line 601, in run_forever\n      self._run_once()\n    File \"C:\\Users\\jainh\\anaconda3\\lib\\asyncio\\base_events.py\", line 1905, in _run_once\n      handle._run()\n    File \"C:\\Users\\jainh\\anaconda3\\lib\\asyncio\\events.py\", line 80, in _run\n      self._context.run(self._callback, *self._args)\n    File \"C:\\Users\\jainh\\anaconda3\\lib\\site-packages\\ipykernel\\kernelbase.py\", line 510, in dispatch_queue\n      await self.process_one()\n    File \"C:\\Users\\jainh\\anaconda3\\lib\\site-packages\\ipykernel\\kernelbase.py\", line 499, in process_one\n      await dispatch(*args)\n    File \"C:\\Users\\jainh\\anaconda3\\lib\\site-packages\\ipykernel\\kernelbase.py\", line 406, in dispatch_shell\n      await result\n    File \"C:\\Users\\jainh\\anaconda3\\lib\\site-packages\\ipykernel\\kernelbase.py\", line 730, in execute_request\n      reply_content = await reply_content\n    File \"C:\\Users\\jainh\\anaconda3\\lib\\site-packages\\ipykernel\\ipkernel.py\", line 390, in do_execute\n      res = shell.run_cell(code, store_history=store_history, silent=silent)\n    File \"C:\\Users\\jainh\\anaconda3\\lib\\site-packages\\ipykernel\\zmqshell.py\", line 528, in run_cell\n      return super().run_cell(*args, **kwargs)\n    File \"C:\\Users\\jainh\\anaconda3\\lib\\site-packages\\IPython\\core\\interactiveshell.py\", line 2914, in run_cell\n      result = self._run_cell(\n    File \"C:\\Users\\jainh\\anaconda3\\lib\\site-packages\\IPython\\core\\interactiveshell.py\", line 2960, in _run_cell\n      return runner(coro)\n    File \"C:\\Users\\jainh\\anaconda3\\lib\\site-packages\\IPython\\core\\async_helpers.py\", line 78, in _pseudo_sync_runner\n      coro.send(None)\n    File \"C:\\Users\\jainh\\anaconda3\\lib\\site-packages\\IPython\\core\\interactiveshell.py\", line 3185, in run_cell_async\n      has_raised = await self.run_ast_nodes(code_ast.body, cell_name,\n    File \"C:\\Users\\jainh\\anaconda3\\lib\\site-packages\\IPython\\core\\interactiveshell.py\", line 3377, in run_ast_nodes\n      if (await self.run_code(code, result,  async_=asy)):\n    File \"C:\\Users\\jainh\\anaconda3\\lib\\site-packages\\IPython\\core\\interactiveshell.py\", line 3457, in run_code\n      exec(code_obj, self.user_global_ns, self.user_ns)\n    File \"C:\\Users\\jainh\\AppData\\Local\\Temp\\ipykernel_13008\\863240012.py\", line 2, in <module>\n      history = model.fit(X_train, y_train,epochs=5,validation_data=(X_test,y_test))\n    File \"C:\\Users\\jainh\\anaconda3\\lib\\site-packages\\keras\\src\\utils\\traceback_utils.py\", line 65, in error_handler\n      return fn(*args, **kwargs)\n    File \"C:\\Users\\jainh\\anaconda3\\lib\\site-packages\\keras\\src\\engine\\training.py\", line 1742, in fit\n      tmp_logs = self.train_function(iterator)\n    File \"C:\\Users\\jainh\\anaconda3\\lib\\site-packages\\keras\\src\\engine\\training.py\", line 1338, in train_function\n      return step_function(self, iterator)\n    File \"C:\\Users\\jainh\\anaconda3\\lib\\site-packages\\keras\\src\\engine\\training.py\", line 1322, in step_function\n      outputs = model.distribute_strategy.run(run_step, args=(data,))\n    File \"C:\\Users\\jainh\\anaconda3\\lib\\site-packages\\keras\\src\\engine\\training.py\", line 1303, in run_step\n      outputs = model.train_step(data)\n    File \"C:\\Users\\jainh\\anaconda3\\lib\\site-packages\\keras\\src\\engine\\training.py\", line 1080, in train_step\n      y_pred = self(x, training=True)\n    File \"C:\\Users\\jainh\\anaconda3\\lib\\site-packages\\keras\\src\\utils\\traceback_utils.py\", line 65, in error_handler\n      return fn(*args, **kwargs)\n    File \"C:\\Users\\jainh\\anaconda3\\lib\\site-packages\\keras\\src\\engine\\training.py\", line 569, in __call__\n      return super().__call__(*args, **kwargs)\n    File \"C:\\Users\\jainh\\anaconda3\\lib\\site-packages\\keras\\src\\utils\\traceback_utils.py\", line 65, in error_handler\n      return fn(*args, **kwargs)\n    File \"C:\\Users\\jainh\\anaconda3\\lib\\site-packages\\keras\\src\\engine\\base_layer.py\", line 1150, in __call__\n      outputs = call_fn(inputs, *args, **kwargs)\n    File \"C:\\Users\\jainh\\anaconda3\\lib\\site-packages\\keras\\src\\utils\\traceback_utils.py\", line 96, in error_handler\n      return fn(*args, **kwargs)\n    File \"C:\\Users\\jainh\\anaconda3\\lib\\site-packages\\keras\\src\\engine\\sequential.py\", line 405, in call\n      return super().call(inputs, training=training, mask=mask)\n    File \"C:\\Users\\jainh\\anaconda3\\lib\\site-packages\\keras\\src\\engine\\functional.py\", line 512, in call\n      return self._run_internal_graph(inputs, training=training, mask=mask)\n    File \"C:\\Users\\jainh\\anaconda3\\lib\\site-packages\\keras\\src\\engine\\functional.py\", line 669, in _run_internal_graph\n      outputs = node.layer(*args, **kwargs)\n    File \"C:\\Users\\jainh\\anaconda3\\lib\\site-packages\\keras\\src\\utils\\traceback_utils.py\", line 65, in error_handler\n      return fn(*args, **kwargs)\n    File \"C:\\Users\\jainh\\anaconda3\\lib\\site-packages\\keras\\src\\engine\\base_layer.py\", line 1150, in __call__\n      outputs = call_fn(inputs, *args, **kwargs)\n    File \"C:\\Users\\jainh\\anaconda3\\lib\\site-packages\\keras\\src\\utils\\traceback_utils.py\", line 96, in error_handler\n      return fn(*args, **kwargs)\n    File \"C:\\Users\\jainh\\anaconda3\\lib\\site-packages\\keras\\src\\layers\\core\\embedding.py\", line 272, in call\n      out = tf.nn.embedding_lookup(self.embeddings, inputs)\nNode: 'sequential_5/embedding_4/embedding_lookup'\nindices[0,1] = 18307 is not in [0, 10000)\n\t [[{{node sequential_5/embedding_4/embedding_lookup}}]] [Op:__inference_train_function_4305]",
     "output_type": "error",
     "traceback": [
      "\u001b[1;31m---------------------------------------------------------------------------\u001b[0m",
      "\u001b[1;31mInvalidArgumentError\u001b[0m                      Traceback (most recent call last)",
      "\u001b[1;32m~\\AppData\\Local\\Temp\\ipykernel_13008\\863240012.py\u001b[0m in \u001b[0;36m<module>\u001b[1;34m\u001b[0m\n\u001b[0;32m      1\u001b[0m \u001b[0mmodel\u001b[0m\u001b[1;33m.\u001b[0m\u001b[0mcompile\u001b[0m\u001b[1;33m(\u001b[0m\u001b[0moptimizer\u001b[0m\u001b[1;33m=\u001b[0m\u001b[1;34m'adam'\u001b[0m\u001b[1;33m,\u001b[0m \u001b[0mloss\u001b[0m\u001b[1;33m=\u001b[0m\u001b[1;34m'binary_crossentropy'\u001b[0m\u001b[1;33m,\u001b[0m \u001b[0mmetrics\u001b[0m\u001b[1;33m=\u001b[0m\u001b[1;33m[\u001b[0m\u001b[1;34m'acc'\u001b[0m\u001b[1;33m]\u001b[0m\u001b[1;33m)\u001b[0m\u001b[1;33m\u001b[0m\u001b[1;33m\u001b[0m\u001b[0m\n\u001b[1;32m----> 2\u001b[1;33m \u001b[0mhistory\u001b[0m \u001b[1;33m=\u001b[0m \u001b[0mmodel\u001b[0m\u001b[1;33m.\u001b[0m\u001b[0mfit\u001b[0m\u001b[1;33m(\u001b[0m\u001b[0mX_train\u001b[0m\u001b[1;33m,\u001b[0m \u001b[0my_train\u001b[0m\u001b[1;33m,\u001b[0m\u001b[0mepochs\u001b[0m\u001b[1;33m=\u001b[0m\u001b[1;36m5\u001b[0m\u001b[1;33m,\u001b[0m\u001b[0mvalidation_data\u001b[0m\u001b[1;33m=\u001b[0m\u001b[1;33m(\u001b[0m\u001b[0mX_test\u001b[0m\u001b[1;33m,\u001b[0m\u001b[0my_test\u001b[0m\u001b[1;33m)\u001b[0m\u001b[1;33m)\u001b[0m\u001b[1;33m\u001b[0m\u001b[1;33m\u001b[0m\u001b[0m\n\u001b[0m",
      "\u001b[1;32m~\\anaconda3\\lib\\site-packages\\keras\\src\\utils\\traceback_utils.py\u001b[0m in \u001b[0;36merror_handler\u001b[1;34m(*args, **kwargs)\u001b[0m\n\u001b[0;32m     68\u001b[0m             \u001b[1;31m# To get the full stack trace, call:\u001b[0m\u001b[1;33m\u001b[0m\u001b[1;33m\u001b[0m\u001b[0m\n\u001b[0;32m     69\u001b[0m             \u001b[1;31m# `tf.debugging.disable_traceback_filtering()`\u001b[0m\u001b[1;33m\u001b[0m\u001b[1;33m\u001b[0m\u001b[0m\n\u001b[1;32m---> 70\u001b[1;33m             \u001b[1;32mraise\u001b[0m \u001b[0me\u001b[0m\u001b[1;33m.\u001b[0m\u001b[0mwith_traceback\u001b[0m\u001b[1;33m(\u001b[0m\u001b[0mfiltered_tb\u001b[0m\u001b[1;33m)\u001b[0m \u001b[1;32mfrom\u001b[0m \u001b[1;32mNone\u001b[0m\u001b[1;33m\u001b[0m\u001b[1;33m\u001b[0m\u001b[0m\n\u001b[0m\u001b[0;32m     71\u001b[0m         \u001b[1;32mfinally\u001b[0m\u001b[1;33m:\u001b[0m\u001b[1;33m\u001b[0m\u001b[1;33m\u001b[0m\u001b[0m\n\u001b[0;32m     72\u001b[0m             \u001b[1;32mdel\u001b[0m \u001b[0mfiltered_tb\u001b[0m\u001b[1;33m\u001b[0m\u001b[1;33m\u001b[0m\u001b[0m\n",
      "\u001b[1;32m~\\anaconda3\\lib\\site-packages\\tensorflow\\python\\eager\\execute.py\u001b[0m in \u001b[0;36mquick_execute\u001b[1;34m(op_name, num_outputs, inputs, attrs, ctx, name)\u001b[0m\n\u001b[0;32m     51\u001b[0m   \u001b[1;32mtry\u001b[0m\u001b[1;33m:\u001b[0m\u001b[1;33m\u001b[0m\u001b[1;33m\u001b[0m\u001b[0m\n\u001b[0;32m     52\u001b[0m     \u001b[0mctx\u001b[0m\u001b[1;33m.\u001b[0m\u001b[0mensure_initialized\u001b[0m\u001b[1;33m(\u001b[0m\u001b[1;33m)\u001b[0m\u001b[1;33m\u001b[0m\u001b[1;33m\u001b[0m\u001b[0m\n\u001b[1;32m---> 53\u001b[1;33m     tensors = pywrap_tfe.TFE_Py_Execute(ctx._handle, device_name, op_name,\n\u001b[0m\u001b[0;32m     54\u001b[0m                                         inputs, attrs, num_outputs)\n\u001b[0;32m     55\u001b[0m   \u001b[1;32mexcept\u001b[0m \u001b[0mcore\u001b[0m\u001b[1;33m.\u001b[0m\u001b[0m_NotOkStatusException\u001b[0m \u001b[1;32mas\u001b[0m \u001b[0me\u001b[0m\u001b[1;33m:\u001b[0m\u001b[1;33m\u001b[0m\u001b[1;33m\u001b[0m\u001b[0m\n",
      "\u001b[1;31mInvalidArgumentError\u001b[0m: Graph execution error:\n\nDetected at node 'sequential_5/embedding_4/embedding_lookup' defined at (most recent call last):\n    File \"C:\\Users\\jainh\\anaconda3\\lib\\runpy.py\", line 197, in _run_module_as_main\n      return _run_code(code, main_globals, None,\n    File \"C:\\Users\\jainh\\anaconda3\\lib\\runpy.py\", line 87, in _run_code\n      exec(code, run_globals)\n    File \"C:\\Users\\jainh\\anaconda3\\lib\\site-packages\\ipykernel_launcher.py\", line 17, in <module>\n      app.launch_new_instance()\n    File \"C:\\Users\\jainh\\anaconda3\\lib\\site-packages\\traitlets\\config\\application.py\", line 846, in launch_instance\n      app.start()\n    File \"C:\\Users\\jainh\\anaconda3\\lib\\site-packages\\ipykernel\\kernelapp.py\", line 712, in start\n      self.io_loop.start()\n    File \"C:\\Users\\jainh\\anaconda3\\lib\\site-packages\\tornado\\platform\\asyncio.py\", line 199, in start\n      self.asyncio_loop.run_forever()\n    File \"C:\\Users\\jainh\\anaconda3\\lib\\asyncio\\base_events.py\", line 601, in run_forever\n      self._run_once()\n    File \"C:\\Users\\jainh\\anaconda3\\lib\\asyncio\\base_events.py\", line 1905, in _run_once\n      handle._run()\n    File \"C:\\Users\\jainh\\anaconda3\\lib\\asyncio\\events.py\", line 80, in _run\n      self._context.run(self._callback, *self._args)\n    File \"C:\\Users\\jainh\\anaconda3\\lib\\site-packages\\ipykernel\\kernelbase.py\", line 510, in dispatch_queue\n      await self.process_one()\n    File \"C:\\Users\\jainh\\anaconda3\\lib\\site-packages\\ipykernel\\kernelbase.py\", line 499, in process_one\n      await dispatch(*args)\n    File \"C:\\Users\\jainh\\anaconda3\\lib\\site-packages\\ipykernel\\kernelbase.py\", line 406, in dispatch_shell\n      await result\n    File \"C:\\Users\\jainh\\anaconda3\\lib\\site-packages\\ipykernel\\kernelbase.py\", line 730, in execute_request\n      reply_content = await reply_content\n    File \"C:\\Users\\jainh\\anaconda3\\lib\\site-packages\\ipykernel\\ipkernel.py\", line 390, in do_execute\n      res = shell.run_cell(code, store_history=store_history, silent=silent)\n    File \"C:\\Users\\jainh\\anaconda3\\lib\\site-packages\\ipykernel\\zmqshell.py\", line 528, in run_cell\n      return super().run_cell(*args, **kwargs)\n    File \"C:\\Users\\jainh\\anaconda3\\lib\\site-packages\\IPython\\core\\interactiveshell.py\", line 2914, in run_cell\n      result = self._run_cell(\n    File \"C:\\Users\\jainh\\anaconda3\\lib\\site-packages\\IPython\\core\\interactiveshell.py\", line 2960, in _run_cell\n      return runner(coro)\n    File \"C:\\Users\\jainh\\anaconda3\\lib\\site-packages\\IPython\\core\\async_helpers.py\", line 78, in _pseudo_sync_runner\n      coro.send(None)\n    File \"C:\\Users\\jainh\\anaconda3\\lib\\site-packages\\IPython\\core\\interactiveshell.py\", line 3185, in run_cell_async\n      has_raised = await self.run_ast_nodes(code_ast.body, cell_name,\n    File \"C:\\Users\\jainh\\anaconda3\\lib\\site-packages\\IPython\\core\\interactiveshell.py\", line 3377, in run_ast_nodes\n      if (await self.run_code(code, result,  async_=asy)):\n    File \"C:\\Users\\jainh\\anaconda3\\lib\\site-packages\\IPython\\core\\interactiveshell.py\", line 3457, in run_code\n      exec(code_obj, self.user_global_ns, self.user_ns)\n    File \"C:\\Users\\jainh\\AppData\\Local\\Temp\\ipykernel_13008\\863240012.py\", line 2, in <module>\n      history = model.fit(X_train, y_train,epochs=5,validation_data=(X_test,y_test))\n    File \"C:\\Users\\jainh\\anaconda3\\lib\\site-packages\\keras\\src\\utils\\traceback_utils.py\", line 65, in error_handler\n      return fn(*args, **kwargs)\n    File \"C:\\Users\\jainh\\anaconda3\\lib\\site-packages\\keras\\src\\engine\\training.py\", line 1742, in fit\n      tmp_logs = self.train_function(iterator)\n    File \"C:\\Users\\jainh\\anaconda3\\lib\\site-packages\\keras\\src\\engine\\training.py\", line 1338, in train_function\n      return step_function(self, iterator)\n    File \"C:\\Users\\jainh\\anaconda3\\lib\\site-packages\\keras\\src\\engine\\training.py\", line 1322, in step_function\n      outputs = model.distribute_strategy.run(run_step, args=(data,))\n    File \"C:\\Users\\jainh\\anaconda3\\lib\\site-packages\\keras\\src\\engine\\training.py\", line 1303, in run_step\n      outputs = model.train_step(data)\n    File \"C:\\Users\\jainh\\anaconda3\\lib\\site-packages\\keras\\src\\engine\\training.py\", line 1080, in train_step\n      y_pred = self(x, training=True)\n    File \"C:\\Users\\jainh\\anaconda3\\lib\\site-packages\\keras\\src\\utils\\traceback_utils.py\", line 65, in error_handler\n      return fn(*args, **kwargs)\n    File \"C:\\Users\\jainh\\anaconda3\\lib\\site-packages\\keras\\src\\engine\\training.py\", line 569, in __call__\n      return super().__call__(*args, **kwargs)\n    File \"C:\\Users\\jainh\\anaconda3\\lib\\site-packages\\keras\\src\\utils\\traceback_utils.py\", line 65, in error_handler\n      return fn(*args, **kwargs)\n    File \"C:\\Users\\jainh\\anaconda3\\lib\\site-packages\\keras\\src\\engine\\base_layer.py\", line 1150, in __call__\n      outputs = call_fn(inputs, *args, **kwargs)\n    File \"C:\\Users\\jainh\\anaconda3\\lib\\site-packages\\keras\\src\\utils\\traceback_utils.py\", line 96, in error_handler\n      return fn(*args, **kwargs)\n    File \"C:\\Users\\jainh\\anaconda3\\lib\\site-packages\\keras\\src\\engine\\sequential.py\", line 405, in call\n      return super().call(inputs, training=training, mask=mask)\n    File \"C:\\Users\\jainh\\anaconda3\\lib\\site-packages\\keras\\src\\engine\\functional.py\", line 512, in call\n      return self._run_internal_graph(inputs, training=training, mask=mask)\n    File \"C:\\Users\\jainh\\anaconda3\\lib\\site-packages\\keras\\src\\engine\\functional.py\", line 669, in _run_internal_graph\n      outputs = node.layer(*args, **kwargs)\n    File \"C:\\Users\\jainh\\anaconda3\\lib\\site-packages\\keras\\src\\utils\\traceback_utils.py\", line 65, in error_handler\n      return fn(*args, **kwargs)\n    File \"C:\\Users\\jainh\\anaconda3\\lib\\site-packages\\keras\\src\\engine\\base_layer.py\", line 1150, in __call__\n      outputs = call_fn(inputs, *args, **kwargs)\n    File \"C:\\Users\\jainh\\anaconda3\\lib\\site-packages\\keras\\src\\utils\\traceback_utils.py\", line 96, in error_handler\n      return fn(*args, **kwargs)\n    File \"C:\\Users\\jainh\\anaconda3\\lib\\site-packages\\keras\\src\\layers\\core\\embedding.py\", line 272, in call\n      out = tf.nn.embedding_lookup(self.embeddings, inputs)\nNode: 'sequential_5/embedding_4/embedding_lookup'\nindices[0,1] = 18307 is not in [0, 10000)\n\t [[{{node sequential_5/embedding_4/embedding_lookup}}]] [Op:__inference_train_function_4305]"
     ]
    }
   ],
   "source": [
    "model.compile(optimizer='adam', loss='binary_crossentropy', metrics=['acc'])\n",
    "history = model.fit(X_train, y_train,epochs=5,validation_data=(X_test,y_test))"
   ]
  },
  {
   "cell_type": "code",
   "execution_count": 29,
   "id": "2ce98da0",
   "metadata": {},
   "outputs": [
    {
     "name": "stdout",
     "output_type": "stream",
     "text": [
      "Epoch 1/5\n"
     ]
    },
    {
     "ename": "InvalidArgumentError",
     "evalue": "Graph execution error:\n\nDetected at node 'sequential_5/embedding_4/embedding_lookup' defined at (most recent call last):\n    File \"C:\\Users\\jainh\\anaconda3\\lib\\runpy.py\", line 197, in _run_module_as_main\n      return _run_code(code, main_globals, None,\n    File \"C:\\Users\\jainh\\anaconda3\\lib\\runpy.py\", line 87, in _run_code\n      exec(code, run_globals)\n    File \"C:\\Users\\jainh\\anaconda3\\lib\\site-packages\\ipykernel_launcher.py\", line 17, in <module>\n      app.launch_new_instance()\n    File \"C:\\Users\\jainh\\anaconda3\\lib\\site-packages\\traitlets\\config\\application.py\", line 846, in launch_instance\n      app.start()\n    File \"C:\\Users\\jainh\\anaconda3\\lib\\site-packages\\ipykernel\\kernelapp.py\", line 712, in start\n      self.io_loop.start()\n    File \"C:\\Users\\jainh\\anaconda3\\lib\\site-packages\\tornado\\platform\\asyncio.py\", line 199, in start\n      self.asyncio_loop.run_forever()\n    File \"C:\\Users\\jainh\\anaconda3\\lib\\asyncio\\base_events.py\", line 601, in run_forever\n      self._run_once()\n    File \"C:\\Users\\jainh\\anaconda3\\lib\\asyncio\\base_events.py\", line 1905, in _run_once\n      handle._run()\n    File \"C:\\Users\\jainh\\anaconda3\\lib\\asyncio\\events.py\", line 80, in _run\n      self._context.run(self._callback, *self._args)\n    File \"C:\\Users\\jainh\\anaconda3\\lib\\site-packages\\ipykernel\\kernelbase.py\", line 510, in dispatch_queue\n      await self.process_one()\n    File \"C:\\Users\\jainh\\anaconda3\\lib\\site-packages\\ipykernel\\kernelbase.py\", line 499, in process_one\n      await dispatch(*args)\n    File \"C:\\Users\\jainh\\anaconda3\\lib\\site-packages\\ipykernel\\kernelbase.py\", line 406, in dispatch_shell\n      await result\n    File \"C:\\Users\\jainh\\anaconda3\\lib\\site-packages\\ipykernel\\kernelbase.py\", line 730, in execute_request\n      reply_content = await reply_content\n    File \"C:\\Users\\jainh\\anaconda3\\lib\\site-packages\\ipykernel\\ipkernel.py\", line 390, in do_execute\n      res = shell.run_cell(code, store_history=store_history, silent=silent)\n    File \"C:\\Users\\jainh\\anaconda3\\lib\\site-packages\\ipykernel\\zmqshell.py\", line 528, in run_cell\n      return super().run_cell(*args, **kwargs)\n    File \"C:\\Users\\jainh\\anaconda3\\lib\\site-packages\\IPython\\core\\interactiveshell.py\", line 2914, in run_cell\n      result = self._run_cell(\n    File \"C:\\Users\\jainh\\anaconda3\\lib\\site-packages\\IPython\\core\\interactiveshell.py\", line 2960, in _run_cell\n      return runner(coro)\n    File \"C:\\Users\\jainh\\anaconda3\\lib\\site-packages\\IPython\\core\\async_helpers.py\", line 78, in _pseudo_sync_runner\n      coro.send(None)\n    File \"C:\\Users\\jainh\\anaconda3\\lib\\site-packages\\IPython\\core\\interactiveshell.py\", line 3185, in run_cell_async\n      has_raised = await self.run_ast_nodes(code_ast.body, cell_name,\n    File \"C:\\Users\\jainh\\anaconda3\\lib\\site-packages\\IPython\\core\\interactiveshell.py\", line 3377, in run_ast_nodes\n      if (await self.run_code(code, result,  async_=asy)):\n    File \"C:\\Users\\jainh\\anaconda3\\lib\\site-packages\\IPython\\core\\interactiveshell.py\", line 3457, in run_code\n      exec(code_obj, self.user_global_ns, self.user_ns)\n    File \"C:\\Users\\jainh\\AppData\\Local\\Temp\\ipykernel_13008\\2070113014.py\", line 2, in <module>\n      history = model.fit(X_train, y_train, epochs=5, validation_data=(X_test, y_test))\n    File \"C:\\Users\\jainh\\anaconda3\\lib\\site-packages\\keras\\src\\utils\\traceback_utils.py\", line 65, in error_handler\n      return fn(*args, **kwargs)\n    File \"C:\\Users\\jainh\\anaconda3\\lib\\site-packages\\keras\\src\\engine\\training.py\", line 1742, in fit\n      tmp_logs = self.train_function(iterator)\n    File \"C:\\Users\\jainh\\anaconda3\\lib\\site-packages\\keras\\src\\engine\\training.py\", line 1338, in train_function\n      return step_function(self, iterator)\n    File \"C:\\Users\\jainh\\anaconda3\\lib\\site-packages\\keras\\src\\engine\\training.py\", line 1322, in step_function\n      outputs = model.distribute_strategy.run(run_step, args=(data,))\n    File \"C:\\Users\\jainh\\anaconda3\\lib\\site-packages\\keras\\src\\engine\\training.py\", line 1303, in run_step\n      outputs = model.train_step(data)\n    File \"C:\\Users\\jainh\\anaconda3\\lib\\site-packages\\keras\\src\\engine\\training.py\", line 1080, in train_step\n      y_pred = self(x, training=True)\n    File \"C:\\Users\\jainh\\anaconda3\\lib\\site-packages\\keras\\src\\utils\\traceback_utils.py\", line 65, in error_handler\n      return fn(*args, **kwargs)\n    File \"C:\\Users\\jainh\\anaconda3\\lib\\site-packages\\keras\\src\\engine\\training.py\", line 569, in __call__\n      return super().__call__(*args, **kwargs)\n    File \"C:\\Users\\jainh\\anaconda3\\lib\\site-packages\\keras\\src\\utils\\traceback_utils.py\", line 65, in error_handler\n      return fn(*args, **kwargs)\n    File \"C:\\Users\\jainh\\anaconda3\\lib\\site-packages\\keras\\src\\engine\\base_layer.py\", line 1150, in __call__\n      outputs = call_fn(inputs, *args, **kwargs)\n    File \"C:\\Users\\jainh\\anaconda3\\lib\\site-packages\\keras\\src\\utils\\traceback_utils.py\", line 96, in error_handler\n      return fn(*args, **kwargs)\n    File \"C:\\Users\\jainh\\anaconda3\\lib\\site-packages\\keras\\src\\engine\\sequential.py\", line 405, in call\n      return super().call(inputs, training=training, mask=mask)\n    File \"C:\\Users\\jainh\\anaconda3\\lib\\site-packages\\keras\\src\\engine\\functional.py\", line 512, in call\n      return self._run_internal_graph(inputs, training=training, mask=mask)\n    File \"C:\\Users\\jainh\\anaconda3\\lib\\site-packages\\keras\\src\\engine\\functional.py\", line 669, in _run_internal_graph\n      outputs = node.layer(*args, **kwargs)\n    File \"C:\\Users\\jainh\\anaconda3\\lib\\site-packages\\keras\\src\\utils\\traceback_utils.py\", line 65, in error_handler\n      return fn(*args, **kwargs)\n    File \"C:\\Users\\jainh\\anaconda3\\lib\\site-packages\\keras\\src\\engine\\base_layer.py\", line 1150, in __call__\n      outputs = call_fn(inputs, *args, **kwargs)\n    File \"C:\\Users\\jainh\\anaconda3\\lib\\site-packages\\keras\\src\\utils\\traceback_utils.py\", line 96, in error_handler\n      return fn(*args, **kwargs)\n    File \"C:\\Users\\jainh\\anaconda3\\lib\\site-packages\\keras\\src\\layers\\core\\embedding.py\", line 272, in call\n      out = tf.nn.embedding_lookup(self.embeddings, inputs)\nNode: 'sequential_5/embedding_4/embedding_lookup'\nindices[0,3] = 21743 is not in [0, 10000)\n\t [[{{node sequential_5/embedding_4/embedding_lookup}}]] [Op:__inference_train_function_5995]",
     "output_type": "error",
     "traceback": [
      "\u001b[1;31m---------------------------------------------------------------------------\u001b[0m",
      "\u001b[1;31mInvalidArgumentError\u001b[0m                      Traceback (most recent call last)",
      "\u001b[1;32m~\\AppData\\Local\\Temp\\ipykernel_13008\\2070113014.py\u001b[0m in \u001b[0;36m<module>\u001b[1;34m\u001b[0m\n\u001b[0;32m      1\u001b[0m \u001b[0mmodel\u001b[0m\u001b[1;33m.\u001b[0m\u001b[0mcompile\u001b[0m\u001b[1;33m(\u001b[0m\u001b[0moptimizer\u001b[0m\u001b[1;33m=\u001b[0m\u001b[1;34m'adam'\u001b[0m\u001b[1;33m,\u001b[0m \u001b[0mloss\u001b[0m\u001b[1;33m=\u001b[0m\u001b[1;34m'binary_crossentropy'\u001b[0m\u001b[1;33m,\u001b[0m \u001b[0mmetrics\u001b[0m\u001b[1;33m=\u001b[0m\u001b[1;33m[\u001b[0m\u001b[1;34m'acc'\u001b[0m\u001b[1;33m]\u001b[0m\u001b[1;33m)\u001b[0m\u001b[1;33m\u001b[0m\u001b[1;33m\u001b[0m\u001b[0m\n\u001b[1;32m----> 2\u001b[1;33m \u001b[0mhistory\u001b[0m \u001b[1;33m=\u001b[0m \u001b[0mmodel\u001b[0m\u001b[1;33m.\u001b[0m\u001b[0mfit\u001b[0m\u001b[1;33m(\u001b[0m\u001b[0mX_train\u001b[0m\u001b[1;33m,\u001b[0m \u001b[0my_train\u001b[0m\u001b[1;33m,\u001b[0m \u001b[0mepochs\u001b[0m\u001b[1;33m=\u001b[0m\u001b[1;36m5\u001b[0m\u001b[1;33m,\u001b[0m \u001b[0mvalidation_data\u001b[0m\u001b[1;33m=\u001b[0m\u001b[1;33m(\u001b[0m\u001b[0mX_test\u001b[0m\u001b[1;33m,\u001b[0m \u001b[0my_test\u001b[0m\u001b[1;33m)\u001b[0m\u001b[1;33m)\u001b[0m\u001b[1;33m\u001b[0m\u001b[1;33m\u001b[0m\u001b[0m\n\u001b[0m",
      "\u001b[1;32m~\\anaconda3\\lib\\site-packages\\keras\\src\\utils\\traceback_utils.py\u001b[0m in \u001b[0;36merror_handler\u001b[1;34m(*args, **kwargs)\u001b[0m\n\u001b[0;32m     68\u001b[0m             \u001b[1;31m# To get the full stack trace, call:\u001b[0m\u001b[1;33m\u001b[0m\u001b[1;33m\u001b[0m\u001b[0m\n\u001b[0;32m     69\u001b[0m             \u001b[1;31m# `tf.debugging.disable_traceback_filtering()`\u001b[0m\u001b[1;33m\u001b[0m\u001b[1;33m\u001b[0m\u001b[0m\n\u001b[1;32m---> 70\u001b[1;33m             \u001b[1;32mraise\u001b[0m \u001b[0me\u001b[0m\u001b[1;33m.\u001b[0m\u001b[0mwith_traceback\u001b[0m\u001b[1;33m(\u001b[0m\u001b[0mfiltered_tb\u001b[0m\u001b[1;33m)\u001b[0m \u001b[1;32mfrom\u001b[0m \u001b[1;32mNone\u001b[0m\u001b[1;33m\u001b[0m\u001b[1;33m\u001b[0m\u001b[0m\n\u001b[0m\u001b[0;32m     71\u001b[0m         \u001b[1;32mfinally\u001b[0m\u001b[1;33m:\u001b[0m\u001b[1;33m\u001b[0m\u001b[1;33m\u001b[0m\u001b[0m\n\u001b[0;32m     72\u001b[0m             \u001b[1;32mdel\u001b[0m \u001b[0mfiltered_tb\u001b[0m\u001b[1;33m\u001b[0m\u001b[1;33m\u001b[0m\u001b[0m\n",
      "\u001b[1;32m~\\anaconda3\\lib\\site-packages\\tensorflow\\python\\eager\\execute.py\u001b[0m in \u001b[0;36mquick_execute\u001b[1;34m(op_name, num_outputs, inputs, attrs, ctx, name)\u001b[0m\n\u001b[0;32m     51\u001b[0m   \u001b[1;32mtry\u001b[0m\u001b[1;33m:\u001b[0m\u001b[1;33m\u001b[0m\u001b[1;33m\u001b[0m\u001b[0m\n\u001b[0;32m     52\u001b[0m     \u001b[0mctx\u001b[0m\u001b[1;33m.\u001b[0m\u001b[0mensure_initialized\u001b[0m\u001b[1;33m(\u001b[0m\u001b[1;33m)\u001b[0m\u001b[1;33m\u001b[0m\u001b[1;33m\u001b[0m\u001b[0m\n\u001b[1;32m---> 53\u001b[1;33m     tensors = pywrap_tfe.TFE_Py_Execute(ctx._handle, device_name, op_name,\n\u001b[0m\u001b[0;32m     54\u001b[0m                                         inputs, attrs, num_outputs)\n\u001b[0;32m     55\u001b[0m   \u001b[1;32mexcept\u001b[0m \u001b[0mcore\u001b[0m\u001b[1;33m.\u001b[0m\u001b[0m_NotOkStatusException\u001b[0m \u001b[1;32mas\u001b[0m \u001b[0me\u001b[0m\u001b[1;33m:\u001b[0m\u001b[1;33m\u001b[0m\u001b[1;33m\u001b[0m\u001b[0m\n",
      "\u001b[1;31mInvalidArgumentError\u001b[0m: Graph execution error:\n\nDetected at node 'sequential_5/embedding_4/embedding_lookup' defined at (most recent call last):\n    File \"C:\\Users\\jainh\\anaconda3\\lib\\runpy.py\", line 197, in _run_module_as_main\n      return _run_code(code, main_globals, None,\n    File \"C:\\Users\\jainh\\anaconda3\\lib\\runpy.py\", line 87, in _run_code\n      exec(code, run_globals)\n    File \"C:\\Users\\jainh\\anaconda3\\lib\\site-packages\\ipykernel_launcher.py\", line 17, in <module>\n      app.launch_new_instance()\n    File \"C:\\Users\\jainh\\anaconda3\\lib\\site-packages\\traitlets\\config\\application.py\", line 846, in launch_instance\n      app.start()\n    File \"C:\\Users\\jainh\\anaconda3\\lib\\site-packages\\ipykernel\\kernelapp.py\", line 712, in start\n      self.io_loop.start()\n    File \"C:\\Users\\jainh\\anaconda3\\lib\\site-packages\\tornado\\platform\\asyncio.py\", line 199, in start\n      self.asyncio_loop.run_forever()\n    File \"C:\\Users\\jainh\\anaconda3\\lib\\asyncio\\base_events.py\", line 601, in run_forever\n      self._run_once()\n    File \"C:\\Users\\jainh\\anaconda3\\lib\\asyncio\\base_events.py\", line 1905, in _run_once\n      handle._run()\n    File \"C:\\Users\\jainh\\anaconda3\\lib\\asyncio\\events.py\", line 80, in _run\n      self._context.run(self._callback, *self._args)\n    File \"C:\\Users\\jainh\\anaconda3\\lib\\site-packages\\ipykernel\\kernelbase.py\", line 510, in dispatch_queue\n      await self.process_one()\n    File \"C:\\Users\\jainh\\anaconda3\\lib\\site-packages\\ipykernel\\kernelbase.py\", line 499, in process_one\n      await dispatch(*args)\n    File \"C:\\Users\\jainh\\anaconda3\\lib\\site-packages\\ipykernel\\kernelbase.py\", line 406, in dispatch_shell\n      await result\n    File \"C:\\Users\\jainh\\anaconda3\\lib\\site-packages\\ipykernel\\kernelbase.py\", line 730, in execute_request\n      reply_content = await reply_content\n    File \"C:\\Users\\jainh\\anaconda3\\lib\\site-packages\\ipykernel\\ipkernel.py\", line 390, in do_execute\n      res = shell.run_cell(code, store_history=store_history, silent=silent)\n    File \"C:\\Users\\jainh\\anaconda3\\lib\\site-packages\\ipykernel\\zmqshell.py\", line 528, in run_cell\n      return super().run_cell(*args, **kwargs)\n    File \"C:\\Users\\jainh\\anaconda3\\lib\\site-packages\\IPython\\core\\interactiveshell.py\", line 2914, in run_cell\n      result = self._run_cell(\n    File \"C:\\Users\\jainh\\anaconda3\\lib\\site-packages\\IPython\\core\\interactiveshell.py\", line 2960, in _run_cell\n      return runner(coro)\n    File \"C:\\Users\\jainh\\anaconda3\\lib\\site-packages\\IPython\\core\\async_helpers.py\", line 78, in _pseudo_sync_runner\n      coro.send(None)\n    File \"C:\\Users\\jainh\\anaconda3\\lib\\site-packages\\IPython\\core\\interactiveshell.py\", line 3185, in run_cell_async\n      has_raised = await self.run_ast_nodes(code_ast.body, cell_name,\n    File \"C:\\Users\\jainh\\anaconda3\\lib\\site-packages\\IPython\\core\\interactiveshell.py\", line 3377, in run_ast_nodes\n      if (await self.run_code(code, result,  async_=asy)):\n    File \"C:\\Users\\jainh\\anaconda3\\lib\\site-packages\\IPython\\core\\interactiveshell.py\", line 3457, in run_code\n      exec(code_obj, self.user_global_ns, self.user_ns)\n    File \"C:\\Users\\jainh\\AppData\\Local\\Temp\\ipykernel_13008\\2070113014.py\", line 2, in <module>\n      history = model.fit(X_train, y_train, epochs=5, validation_data=(X_test, y_test))\n    File \"C:\\Users\\jainh\\anaconda3\\lib\\site-packages\\keras\\src\\utils\\traceback_utils.py\", line 65, in error_handler\n      return fn(*args, **kwargs)\n    File \"C:\\Users\\jainh\\anaconda3\\lib\\site-packages\\keras\\src\\engine\\training.py\", line 1742, in fit\n      tmp_logs = self.train_function(iterator)\n    File \"C:\\Users\\jainh\\anaconda3\\lib\\site-packages\\keras\\src\\engine\\training.py\", line 1338, in train_function\n      return step_function(self, iterator)\n    File \"C:\\Users\\jainh\\anaconda3\\lib\\site-packages\\keras\\src\\engine\\training.py\", line 1322, in step_function\n      outputs = model.distribute_strategy.run(run_step, args=(data,))\n    File \"C:\\Users\\jainh\\anaconda3\\lib\\site-packages\\keras\\src\\engine\\training.py\", line 1303, in run_step\n      outputs = model.train_step(data)\n    File \"C:\\Users\\jainh\\anaconda3\\lib\\site-packages\\keras\\src\\engine\\training.py\", line 1080, in train_step\n      y_pred = self(x, training=True)\n    File \"C:\\Users\\jainh\\anaconda3\\lib\\site-packages\\keras\\src\\utils\\traceback_utils.py\", line 65, in error_handler\n      return fn(*args, **kwargs)\n    File \"C:\\Users\\jainh\\anaconda3\\lib\\site-packages\\keras\\src\\engine\\training.py\", line 569, in __call__\n      return super().__call__(*args, **kwargs)\n    File \"C:\\Users\\jainh\\anaconda3\\lib\\site-packages\\keras\\src\\utils\\traceback_utils.py\", line 65, in error_handler\n      return fn(*args, **kwargs)\n    File \"C:\\Users\\jainh\\anaconda3\\lib\\site-packages\\keras\\src\\engine\\base_layer.py\", line 1150, in __call__\n      outputs = call_fn(inputs, *args, **kwargs)\n    File \"C:\\Users\\jainh\\anaconda3\\lib\\site-packages\\keras\\src\\utils\\traceback_utils.py\", line 96, in error_handler\n      return fn(*args, **kwargs)\n    File \"C:\\Users\\jainh\\anaconda3\\lib\\site-packages\\keras\\src\\engine\\sequential.py\", line 405, in call\n      return super().call(inputs, training=training, mask=mask)\n    File \"C:\\Users\\jainh\\anaconda3\\lib\\site-packages\\keras\\src\\engine\\functional.py\", line 512, in call\n      return self._run_internal_graph(inputs, training=training, mask=mask)\n    File \"C:\\Users\\jainh\\anaconda3\\lib\\site-packages\\keras\\src\\engine\\functional.py\", line 669, in _run_internal_graph\n      outputs = node.layer(*args, **kwargs)\n    File \"C:\\Users\\jainh\\anaconda3\\lib\\site-packages\\keras\\src\\utils\\traceback_utils.py\", line 65, in error_handler\n      return fn(*args, **kwargs)\n    File \"C:\\Users\\jainh\\anaconda3\\lib\\site-packages\\keras\\src\\engine\\base_layer.py\", line 1150, in __call__\n      outputs = call_fn(inputs, *args, **kwargs)\n    File \"C:\\Users\\jainh\\anaconda3\\lib\\site-packages\\keras\\src\\utils\\traceback_utils.py\", line 96, in error_handler\n      return fn(*args, **kwargs)\n    File \"C:\\Users\\jainh\\anaconda3\\lib\\site-packages\\keras\\src\\layers\\core\\embedding.py\", line 272, in call\n      out = tf.nn.embedding_lookup(self.embeddings, inputs)\nNode: 'sequential_5/embedding_4/embedding_lookup'\nindices[0,3] = 21743 is not in [0, 10000)\n\t [[{{node sequential_5/embedding_4/embedding_lookup}}]] [Op:__inference_train_function_5995]"
     ]
    }
   ],
   "source": [
    "model.compile(optimizer='adam', loss='binary_crossentropy', metrics=['acc'])\n",
    "history = model.fit(X_train, y_train, epochs=5, validation_data=(X_test, y_test))\n"
   ]
  },
  {
   "cell_type": "code",
   "execution_count": 30,
   "id": "41fc07f0",
   "metadata": {},
   "outputs": [],
   "source": [
    "import tensorflow as tf\n",
    "tf.keras.backend.clear_session()\n"
   ]
  },
  {
   "cell_type": "code",
   "execution_count": null,
   "id": "bf02be8c",
   "metadata": {},
   "outputs": [],
   "source": []
  }
 ],
 "metadata": {
  "kernelspec": {
   "display_name": "Python 3 (ipykernel)",
   "language": "python",
   "name": "python3"
  },
  "language_info": {
   "codemirror_mode": {
    "name": "ipython",
    "version": 3
   },
   "file_extension": ".py",
   "mimetype": "text/x-python",
   "name": "python",
   "nbconvert_exporter": "python",
   "pygments_lexer": "ipython3",
   "version": "3.9.13"
  }
 },
 "nbformat": 4,
 "nbformat_minor": 5
}
